2022-03-23 14:16:12.061 | ERROR    | conf.logger:log_request_error:16 - uid: '', requst: HTTPServerRequest(protocol='http', host='127.0.0.1:8000', method='POST', uri='/v1/login/', version='HTTP/1.1', remote_ip='127.0.0.1'), query: '', body b'{\n    "phone": "18856931381",\n    "password": "123456"\n}'
Traceback (most recent call last):

  File "/Users/qiangchen/Desktop/Labs/Sao/venv/lib/python3.9/site-packages/tornado/web.py", line 1702, in _execute
    result = method(*self.path_args, **self.path_kwargs)
             │       │    │            │    └ {}
             │       │    │            └ <views.login.login_views.LoginHandler object at 0x7f907221a1f0>
             │       │    └ []
             │       └ <views.login.login_views.LoginHandler object at 0x7f907221a1f0>
             └ <bound method LoginHandler.post of <views.login.login_views.LoginHandler object at 0x7f907221a1f0>>

  File "/Users/qiangchen/Desktop/Labs/Sao/views/login/login_views.py", line 22, in post
    self._login_with_password(phone, password)
    │    │                    │      └ '123456'
    │    │                    └ '18856931381'
    │    └ <function LoginHandler._login_with_password at 0x7f90721cd310>
    └ <views.login.login_views.LoginHandler object at 0x7f907221a1f0>

  File "/Users/qiangchen/Desktop/Labs/Sao/views/login/login_views.py", line 38, in _login_with_password
    assert validate_password(user.password, password), '密码错误'
           │                 │    │         └ '123456'
           │                 │    └ <sqlalchemy.orm.attributes.InstrumentedAttribute object at 0x7f9072135860>
           │                 └ <models.user_model.User object at 0x7f90723297f0>
           └ <function validate_password at 0x7f90721cd1f0>

AssertionError: 密码错误
